[=== Module cuda/10.0 loaded ===]
[=== Module cuda/10.0/cudnn/7.6 loaded ===]
Traceback (most recent call last):
  File "hyper_tune.py", line 264, in <module>
    app.run(main)
  File "/network/home/cheluver/miniconda3/envs/new/lib/python3.6/site-packages/absl/app.py", line 299, in run
    _run_main(main, args)
  File "/network/home/cheluver/miniconda3/envs/new/lib/python3.6/site-packages/absl/app.py", line 250, in _run_main
    sys.exit(main(argv))
  File "hyper_tune.py", line 39, in main
    run_for_agent(FLAGS.agent, lr_vanilla)
  File "hyper_tune.py", line 69, in run_for_agent
    best_fieldnames.remove("lr_ctrl")
ValueError: list.remove(x): x not in list
[=== Module cuda/10.0 loaded ===]
[=== Module cuda/10.0/cudnn/7.6 loaded ===]
2020-04-29 10:21:08.486102: E external/org_tensorflow/tensorflow/stream_executor/cuda/cuda_driver.cc:313] failed call to cuInit: CUDA_ERROR_NO_DEVICE: no CUDA-capable device is detected
2020-04-29 10:21:08.714876: E tensorflow/stream_executor/cuda/cuda_driver.cc:318] failed call to cuInit: CUDA_ERROR_NO_DEVICE: no CUDA-capable device is detected
/network/home/cheluver/miniconda3/envs/new/lib/python3.6/site-packages/jax/lib/xla_bridge.py:122: UserWarning: No GPU/TPU found, falling back to CPU.
  warnings.warn('No GPU/TPU found, falling back to CPU.')
